2019-07-29 16:07:17,427	INFO -- Settings: TopologyGenerator/settings-php_apache_no_node_removal.json
2019-07-29 16:07:17,549	INFO -- Graphdatabase emptied
2019-07-29 16:07:17,549	INFO -- Waiting for warmup to finish. 1800 seconds
2019-07-29 16:37:17,646	INFO -- Going to sleep for 240 seconds
2019-07-29 16:41:17,745	INFO -- Time for an update_step iteration! 2019-07-29 16:41:17.745955
2019-07-29 16:41:18,275	INFO -- Cluster was stable for 240 seconds till 2019-07-29 16:41:17.746275, calculating best transition
2019-07-29 16:41:18,277	ERROR -- HTTPConnectionPool(host='localhost', port=8080): Max retries exceeded with url: /api/v1/pods (Caused by NewConnectionError('<urllib3.connection.HTTPConnection object at 0x7f78f9a2c550>: Failed to establish a new connection: [Errno 111] Connection refused'))
Traceback (most recent call last):
  File "/usr/lib/python3/dist-packages/urllib3/connection.py", line 159, in _new_conn
    (self._dns_host, self.port), self.timeout, **extra_kw)
  File "/usr/lib/python3/dist-packages/urllib3/util/connection.py", line 80, in create_connection
    raise err
  File "/usr/lib/python3/dist-packages/urllib3/util/connection.py", line 70, in create_connection
    sock.connect(sa)
ConnectionRefusedError: [Errno 111] Connection refused

During handling of the above exception, another exception occurred:

Traceback (most recent call last):
  File "/usr/lib/python3/dist-packages/urllib3/connectionpool.py", line 600, in urlopen
    chunked=chunked)
  File "/usr/lib/python3/dist-packages/urllib3/connectionpool.py", line 354, in _make_request
    conn.request(method, url, **httplib_request_kw)
  File "/usr/lib/python3.7/http/client.py", line 1229, in request
    self._send_request(method, url, body, headers, encode_chunked)
  File "/usr/lib/python3.7/http/client.py", line 1275, in _send_request
    self.endheaders(body, encode_chunked=encode_chunked)
  File "/usr/lib/python3.7/http/client.py", line 1224, in endheaders
    self._send_output(message_body, encode_chunked=encode_chunked)
  File "/usr/lib/python3.7/http/client.py", line 1016, in _send_output
    self.send(msg)
  File "/usr/lib/python3.7/http/client.py", line 956, in send
    self.connect()
  File "/usr/lib/python3/dist-packages/urllib3/connection.py", line 181, in connect
    conn = self._new_conn()
  File "/usr/lib/python3/dist-packages/urllib3/connection.py", line 168, in _new_conn
    self, "Failed to establish a new connection: %s" % e)
urllib3.exceptions.NewConnectionError: <urllib3.connection.HTTPConnection object at 0x7f78f9a2c550>: Failed to establish a new connection: [Errno 111] Connection refused

During handling of the above exception, another exception occurred:

Traceback (most recent call last):
  File "/usr/lib/python3/dist-packages/requests/adapters.py", line 449, in send
    timeout=timeout
  File "/usr/lib/python3/dist-packages/urllib3/connectionpool.py", line 638, in urlopen
    _stacktrace=sys.exc_info()[2])
  File "/usr/lib/python3/dist-packages/urllib3/util/retry.py", line 398, in increment
    raise MaxRetryError(_pool, url, error or ResponseError(cause))
urllib3.exceptions.MaxRetryError: HTTPConnectionPool(host='localhost', port=8080): Max retries exceeded with url: /api/v1/pods (Caused by NewConnectionError('<urllib3.connection.HTTPConnection object at 0x7f78f9a2c550>: Failed to establish a new connection: [Errno 111] Connection refused'))

During handling of the above exception, another exception occurred:

Traceback (most recent call last):
  File "/media/thijs/SSD2/University/2018-2019/Thesis/DynamicTopologySelection/TopologyGenerator/SmartKubernetesSchedular/moderator.py", line 202, in main
    tuning_loop(time_window, load_extractor, settings)
  File "/media/thijs/SSD2/University/2018-2019/Thesis/DynamicTopologySelection/TopologyGenerator/SmartKubernetesSchedular/moderator.py", line 155, in tuning_loop
    while not update_step(time_window, load_extractor, settings):
  File "/media/thijs/SSD2/University/2018-2019/Thesis/DynamicTopologySelection/TopologyGenerator/SmartKubernetesSchedular/moderator.py", line 123, in update_step
    pods = extract_pods.extract_all_pods()
  File "/media/thijs/SSD2/University/2018-2019/Thesis/DynamicTopologySelection/TopologyGenerator/kubernetes_tools/extract_pods.py", line 114, in extract_all_pods
    pods_info = requests.get("http://localhost:8080/api/v1/pods").json()
  File "/usr/lib/python3/dist-packages/requests/api.py", line 75, in get
    return request('get', url, params=params, **kwargs)
  File "/usr/lib/python3/dist-packages/requests/api.py", line 60, in request
    return session.request(method=method, url=url, **kwargs)
  File "/usr/lib/python3/dist-packages/requests/sessions.py", line 533, in request
    resp = self.send(prep, **send_kwargs)
  File "/usr/lib/python3/dist-packages/requests/sessions.py", line 646, in send
    r = adapter.send(request, **kwargs)
  File "/usr/lib/python3/dist-packages/requests/adapters.py", line 516, in send
    raise ConnectionError(e, request=request)
requests.exceptions.ConnectionError: HTTPConnectionPool(host='localhost', port=8080): Max retries exceeded with url: /api/v1/pods (Caused by NewConnectionError('<urllib3.connection.HTTPConnection object at 0x7f78f9a2c550>: Failed to establish a new connection: [Errno 111] Connection refused'))
